Workbook

Sheet Sidewalk Projects - All
B3: Capital Facilities Plan- Sidewalks | AK3: Sidewalks - Scoring Criteria
B4: Project Number | C4: TBD Project List | D4: Roadway | E4: Start | F4: End | G4: Description | H4: Grant Award | I4: Grant Source | J4: Budget | K4: Sidewalk Length | L4: Cost/LF | M4: Multi-Use Path | N4: Cost/LF2 | O4: Ramps | P4: Cost/Ea | Q4: RRFB | R4: Cost/Each | S4: Const. Estimate | T4: Engineering | U4: ROW | V4: Contingency | W4: Total Cost | X4: 2015 Cost Estimates | Y4: Percent Change | Z4: Zoning | AA4: Zoning Score | AB4: Functional Classification | AC4: Vehicle on Ped Accident Data | AD4: Facility within 1/4 Mile | AE4: Cost | AF4: Opportunity | AG4: Grant Eligibility | AH4: Dedicated Funding | AI4: Average Score | AK4: Priority | AL4: Zoning | AM4: Roadway Type | AN4: Pedestrian/Bicycle Accidents | AO4: Facility within 1/4 Mile | AP4: Cost | AQ4: Opportunity | AR4: Grant Eligibility | AS4: Dedicated Funding
A5: 1 | B5: CP-101 | C5: TBD -01 | D5: 16th Street NE | E5: Main Street | F5: Machias Cutoff | G5: Construction of an MUP to connect downtown Lake Stevens to the Centennial Trail. | H5: 2500000 | I5: Federal Capital Transportation | S5: 3600000 | T5: 600000 | U5: 270000 | W5: =SUM(S5:V5) -> 4470000 | X5: 287000 | Y5: =W5/X5 -> 15.574913 | Z5: Multi-Family | AA5: 2 | AB5: 2 | AC5: 2 | AD5: 3 | AE5: =IF(W5<150000,"3",IF(W5<500000,"2",IF(W5>500000,"1"))) -> 1 | AF5: 3 | AG5: 3 | AH5: 2 | AI5: {=SUM(AA5:AH5/8)} -> 2.25 | AK5: High = 3 | AL5: Commercial, incl. School | AM5: Minor Arterial | AN5: More than one Ped/Bicycle Accident | AO5: Adjacent to a medical office | AP5: <$150,000 | AQ5: Public & Political Support is Strong | AR5: Eligible for more than two grants | AS5: Full Funding
A6: 2 | B6: CP-102 | C6: TBD-12 | D6: 123rd Ave NE | E6: 22nd Street NE | F6: North Lakeshore Drive | K6: 650 | L6: 400 | N6: 600 | O6: 10 | P6: 4000 | R6: 2500 | S6: =K6*L6+O6*P6+Q6*R6+M6*N6 -> 300000 | T6: =S6*0.1 -> 30000 | U6: =S6*0.07 -> 21000 | V6: =SUM(S6:U6)*0.2 -> 70200 | W6: =SUM(S6:V6) -> 421200 | X6: 120000 | Y6: =W6/X6 -> 3.51 | Z6: Commercial | AA6: 3 | AB6: 1 | AC6: 1 | AD6: 3 | AE6: =IF(W6<150000,"3",IF(W6<500000,"2",IF(W6>500000,"1"))) -> 2 | AF6: 2 | AG6: 2 | AH6: 1 | AI6: {=SUM(AA6:AH6/8)} -> 1.875 | AM6: Collisions involving pedestrians | AO6: Adjacent to services for the disabled
A7: 3 | B7: CP-103 | C7: TBD-11 | D7: Hartford Drive | E7: 20th St NE | F7: 21st Street NE | K7: 500 | L7: 400 | N7: 600 | O7: 4 | P7: 4000 | R7: 2500 | S7: =K7*L7+O7*P7+Q7*R7+M7*N7 -> 216000 | T7: =S7*0.1 -> 21600 | U7: =S7*0.07 -> 15120 | V7: =SUM(S7:U7)*0.2 -> 50544 | W7: =SUM(S7:V7) -> 303264 | X7: 81000 | Y7: =W7/X7 -> 3.744 | Z7: Commercial | AA7: 3 | AB7: 2 | AC7: 1 | AD7: 3 | AE7: =IF(W7<150000,"3",IF(W7<500000,"2",IF(W7>500000,"1"))) -> 2 | AF7: 3 | AG7: 1 | AH7: 1 | AI7: {=SUM(AA7:AH7/8)} -> 2 | AM7: Streets with highway interchange | AO7: Adjacent to a library
A8: 4 | B8: CP-104 | C8: TBD-10 | D8: Grade Road | E8: Hartford Drive | F8: Library | K8: 650 | L8: 400 | N8: 600 | O8: 2 | P8: 4000 | Q8: 2 | R8: 2500 | S8: =K8*L8+O8*P8+Q8*R8+M8*N8 -> 273000 | T8: =S8*0.1 -> 27300 | U8: =S8*0.07 -> 19110 | V8: =SUM(S8:U8)*0.2 -> 63882 | W8: =SUM(S8:V8) -> 383292 | X8: 135000 | Y8: =W8/X8 -> 2.8392 | Z8: Commercial | AA8: 3 | AB8: 2 | AC8: 1 | AD8: 3 | AE8: =IF(W8<150000,"3",IF(W8<500000,"2",IF(W8>500000,"1"))) -> 2 | AF8: 3 | AG8: 1 | AH8: 1 | AI8: {=SUM(AA8:AH8/8)} -> 2 | AO8: Adjacent to a senior center or senior housing
A9: 5 | B9: CP-105 | D9: Grade Road | E9: 30th Street NE | F9: 32nd Street NE | K9: 500 | L9: 400 | N9: 600 | O9: 4 | P9: 4000 | R9: 2500 | S9: =K9*L9+O9*P9+Q9*R9+M9*N9 -> 216000 | T9: =S9*0.1 -> 21600 | U9: =S9*0.07 -> 15120 | V9: =SUM(S9:U9)*0.2 -> 50544 | W9: =SUM(S9:V9) -> 303264 | X9: 173000 | Y9: =W9/X9 -> 1.7529711 | Z9: Single Family | AA9: 1 | AB9: 2 | AC9: 2 | AD9: 2 | AE9: =IF(W9<150000,"3",IF(W9<500000,"2",IF(W9>500000,"1"))) -> 2 | AF9: 3 | AG9: 1 | AH9: 1 | AI9: {=SUM(AA9:AH9/8)} -> 1.75 | AO9: Adjacent to a school
A10: 6 | B10: CP-106 | D10: Cedar Road | E10: 20th Street NE | F10: Forest Road | K10: 1400 | L10: 400 | N10: 600 | O10: 2 | P10: 4000 | R10: 2500 | S10: =K10*L10+O10*P10+Q10*R10+M10*N10 -> 568000 | T10: =S10*0.1 -> 56800 | U10: =S10*0.07 -> 39760 | V10: =SUM(S10:U10)*0.2 -> 132912 | W10: =SUM(S10:V10) -> 797472 | X10: 209000 | Y10: =W10/X10 -> 3.8156555 | Z10: Single Family | AA10: 1 | AB10: 1 | AC10: 1 | AD10: 1 | AE10: =IF(W10<150000,"3",IF(W10<500000,"2",IF(W10>500000,"1"))) -> 1 | AF10: 1 | AG10: 1 | AH10: 1 | AI10: {=SUM(AA10:AH10/8)} -> 1 | AO10: Adjacent to a high use transit stop
A11: 7 | B11: CP-107 | C11: TBD-04 | D11: 117th Ave NE | E11: 20th Street NE | F11: 26th Street NE | G11: TBD sidewalk along one side of 117th Ave NE between 20th St and26th St. Includes ROW and typical frontage improvements including stormwater. | S11: 1170000 | T11: 290000 | W11: =SUM(S11:V11) -> 1460000 | X11: 434000 | Y11: =W11/X11 -> 3.3640553 | Z11: Single Family | AA11: 1 | AB11: 2 | AC11: 3 | AD11: 3 | AE11: =IF(W11<150000,"3",IF(W11<500000,"2",IF(W11>500000,"1"))) -> 1 | AF11: 2 | AG11: 2 | AH11: 3 | AI11: {=SUM(AA11:AH11/8)} -> 2.125
A12: 8 | B12: CP-108 | D12: Lake View Drive | E12: 112th DR NE | F12: Callow Road | K12: 3000 | L12: 400 | N12: 600 | O12: 8 | P12: 4000 | R12: 2500 | S12: =K12*L12+O12*P12+Q12*R12+M12*N12 -> 1232000 | T12: =S12*0.1 -> 123200 | U12: =S12*0.07 -> 86240 | V12: =SUM(S12:U12)*0.2 -> 288288 | W12: =SUM(S12:V12) -> 1729728 | X12: 1070000 | Y12: =W12/X12 -> 1.6165682 | Z12: Single Family | AA12: 1 | AB12: 2 | AC12: 1 | AD12: 1 | AE12: =IF(W12<150000,"3",IF(W12<500000,"2",IF(W12>500000,"1"))) -> 1 | AF12: 3 | AG12: 2 | AH12: 1 | AI12: {=SUM(AA12:AH12/8)} -> 1.5 | AK12: Medium = 2 | AL12: Mixed Use | AM12: Major Collector | AN12: One Ped/Bicycle Accident | AO12: Adjacent to a public office | AP12: $150,001 to $500,000 | AQ12: Public or Political Support Strong | AR12: Eligible for one grant | AS12: >50% Funded
A13: 9 | B13: CP-110 | D13: Cedar Road | E13: Forest Road | F13: 28th Street NE | K13: 1400 | L13: 400 | N13: 600 | P13: 4000 | R13: 2500 | S13: =K13*L13+O13*P13+Q13*R13+M13*N13 -> 560000 | T13: =S13*0.1 -> 56000 | U13: =S13*0.07 -> 39200 | V13: =SUM(S13:U13)*0.2 -> 131040 | W13: =SUM(S13:V13) -> 786240 | X13: 523000 | Y13: =W13/X13 -> 1.503327 | Z13: Single Family | AA13: 1 | AB13: 1 | AC13: 1 | AD13: 3 | AE13: =IF(W13<150000,"3",IF(W13<500000,"2",IF(W13>500000,"1"))) -> 1 | AF13: 1 | AG13: 1 | AH13: 1 | AI13: {=SUM(AA13:AH13/8)} -> 1.25 | AM13: Minor Collector
A14: 10 | B14: CP-111 | D14: Lake Drive | E14: Lundeen Parkway | F14: 28th Street NE | K14: 1500 | L14: 400 | N14: 600 | O14: 2 | P14: 4000 | R14: 2500 | S14: =K14*L14+O14*P14+Q14*R14+M14*N14 -> 608000 | T14: =S14*0.1 -> 60800 | U14: =S14*0.07 -> 42560 | V14: =SUM(S14:U14)*0.2 -> 142272 | W14: =SUM(S14:V14) -> 853632 | X14: 597000 | Y14: =W14/X14 -> 1.4298693 | Z14: Single Family | AA14: 1 | AB14: 2 | AC14: 1 | AD14: 1 | AE14: =IF(W14<150000,"3",IF(W14<500000,"2",IF(W14>500000,"1"))) -> 1 | AF14: 1 | AG14: 1 | AH14: 1 | AI14: {=SUM(AA14:AH14/8)} -> 1.125 | AO14: Adjacent to a park
A15: 11 | B15: CP-112 | C15: TBD-07 | D15: Soper Hill | E15: Lake Drive | F15: RAB at SR9 | G15: TBD sidewalk along one side of Soper Hill Rd between Lake Dr and SR9. Includes ROW and typical frontage improvements including stormwater. | S15: 1100000 | T15: 275000 | W15: =SUM(S15:V15) -> 1375000 | X15: 1031000 | Y15: =W15/X15 -> 1.3336566 | Z15: Commercial | AA15: 3 | AB15: 3 | AC15: 1 | AD15: 3 | AE15: =IF(W15<150000,"3",IF(W15<500000,"2",IF(W15>500000,"1"))) -> 1 | AF15: 3 | AG15: 2 | AH15: 1 | AI15: {=SUM(AA15:AH15/8)} -> 2.125
A16: 12 | B16: CP-116 | C16: TBD-20 | D16: 4th Street NE | E16: 97th Drive NE | F16: 98th Drive NE | K16: 450 | L16: 400 | N16: 600 | O16: 2 | P16: 4000 | R16: 2500 | S16: =K16*L16+O16*P16+Q16*R16+M16*N16 -> 188000 | T16: =S16*0.1 -> 18800 | U16: =S16*0.07 -> 13160 | V16: =SUM(S16:U16)*0.2 -> 43992 | W16: =SUM(S16:V16) -> 263952 | X16: 163000 | Y16: =W16/X16 -> 1.6193374 | Z16: Multi-Family | AA16: 2 | AB16: 1 | AC16: 1 | AD16: 3 | AE16: =IF(W16<150000,"3",IF(W16<500000,"2",IF(W16>500000,"1"))) -> 2 | AF16: 2 | AG16: 1 | AH16: 1 | AI16: {=SUM(AA16:AH16/8)} -> 1.625
A17: 13 | B17: CP-117 | D17: 99th Ave NE | E17: Lakemont Avenue | F17: 3rd Street NE | K17: 550 | L17: 400 | N17: 600 | O17: 2 | P17: 4000 | R17: 2500 | S17: =K17*L17+O17*P17+Q17*R17+M17*N17 -> 228000 | T17: =S17*0.1 -> 22800 | U17: =S17*0.07 -> 15960 | V17: =SUM(S17:U17)*0.2 -> 53352 | W17: =SUM(S17:V17) -> 320112 | X17: 230000 | Y17: =W17/X17 -> 1.3917913 | Z17: Single Family | AA17: 1 | AB17: 1 | AC17: 1 | AD17: 3 | AE17: =IF(W17<150000,"3",IF(W17<500000,"2",IF(W17>500000,"1"))) -> 2 | AF17: 2 | AG17: 1 | AH17: 1 | AI17: {=SUM(AA17:AH17/8)} -> 1.5 | AK17: Low = 1 | AL17: Single Family | AM17: Neighborhood | AN17: No Record | AO17: Connects or completes street(s) | AP17: >$500,000 | AQ17: Support Not Known/Not Supportive | AR17: Eligibility Unknown | AS17: <50% Funded
A18: 14 | B18: CP-118 | C18: TBD-14 | D18: 99th Ave NE | E18: 1st Street NE | F18: Chapel Hill Road | K18: 160 | L18: 400 | N18: 600 | O18: 2 | P18: 4000 | R18: 2500 | S18: =K18*L18+O18*P18+Q18*R18+M18*N18 -> 72000 | T18: =S18*0.1 -> 7200 | U18: =S18*0.07 -> 5040 | V18: =SUM(S18:U18)*0.2 -> 16848 | W18: =SUM(S18:V18) -> 101088 | X18: 198000 | Y18: =W18/X18 -> 0.51054545 | Z18: Multi-Family | AA18: 2 | AB18: 2 | AC18: 1 | AD18: 3 | AE18: =IF(W18<150000,"3",IF(W18<500000,"2",IF(W18>500000,"1"))) -> 3 | AF18: 2 | AG18: 1 | AH18: 1 | AI18: {=SUM(AA18:AH18/8)} -> 1.875 | AL18: Industrial
A19: 15 | B19: CP-119 | D19: 99th Ave NE | E19: Market Place | F19: 4th Street SE | K19: 1350 | L19: 400 | N19: 600 | O19: 4 | P19: 4000 | R19: 2500 | S19: =K19*L19+O19*P19+Q19*R19+M19*N19 -> 556000 | T19: =S19*0.1 -> 55600 | U19: =S19*0.07 -> 38920 | V19: =SUM(S19:U19)*0.2 -> 130104 | W19: =SUM(S19:V19) -> 780624 | X19: 507000 | Y19: =W19/X19 -> 1.5396923 | Z19: Single Family | AA19: 1 | AB19: 2 | AC19: 1 | AD19: 3 | AE19: =IF(W19<150000,"3",IF(W19<500000,"2",IF(W19>500000,"1"))) -> 1 | AF19: 2 | AG19: 1 | AH19: 1 | AI19: {=SUM(AA19:AH19/8)} -> 1.5
A20: 16 | B20: CP-120 | D20: 99th Ave SE | E20: 11th Place SE | F20: 4th Street SE | K20: 2500 | L20: 400 | N20: 600 | O20: 6 | P20: 4000 | R20: 2500 | S20: =K20*L20+O20*P20+Q20*R20+M20*N20 -> 1024000 | T20: =S20*0.1 -> 102400 | U20: =S20*0.07 -> 71680 | V20: =SUM(S20:U20)*0.2 -> 239616 | W20: =SUM(S20:V20) -> 1437696 | X20: 159000 | Y20: =W20/X20 -> 9.0421132 | Z20: Single Family | AA20: 1 | AB20: 2 | AC20: 1 | AD20: 1 | AE20: =IF(W20<150000,"3",IF(W20<500000,"2",IF(W20>500000,"1"))) -> 1 | AF20: 2 | AG20: 1 | AH20: 1 | AI20: {=SUM(AA20:AH20/8)} -> 1.25
A21: 17 | B21: CP-121 | D21: 32nd Street NE | E21: Grade Road | F21: 118th Drive NE | K21: 450 | L21: 400 | N21: 600 | O21: 2 | P21: 4000 | R21: 2500 | S21: =K21*L21+O21*P21+Q21*R21+M21*N21 -> 188000 | T21: =S21*0.1 -> 18800 | U21: =S21*0.07 -> 13160 | V21: =SUM(S21:U21)*0.2 -> 43992 | W21: =SUM(S21:V21) -> 263952 | X21: 814000 | Y21: =W21/X21 -> 0.32426536 | Z21: Single Family | AA21: 1 | AB21: 1 | AC21: 1 | AD21: 1 | AE21: =IF(W21<150000,"3",IF(W21<500000,"2",IF(W21>500000,"1"))) -> 2 | AF21: 1 | AG21: 1 | AH21: 1 | AI21: {=SUM(AA21:AH21/8)} -> 1.125
A22: 18 | B22: CP-122 | D22: 8th Street SE | E22: 79th Ave SE | F22: 83rd Ave SE | K22: 1300 | L22: 400 | N22: 600 | O22: 3 | P22: 4000 | R22: 2500 | S22: =K22*L22+O22*P22+Q22*R22+M22*N22 -> 532000 | T22: =S22*0.1 -> 53200 | U22: =S22*0.07 -> 37240 | V22: =SUM(S22:U22)*0.2 -> 124488 | W22: =SUM(S22:V22) -> 746928 | X22: 476000 | Y22: =W22/X22 -> 1.5691765 | Z22: Single Family | AA22: 1 | AB22: 2 | AC22: 1 | AD22: 1 | AE22: =IF(W22<150000,"3",IF(W22<500000,"2",IF(W22>500000,"1"))) -> 1 | AF22: 2 | AG22: 1 | AH22: 1 | AI22: {=SUM(AA22:AH22/8)} -> 1.25 | AK22: Adjacent is within 1/4 mile
A23: 19 | B23: CP-123 | D23: 79th Ave SE | E23: 8th Street SE | F23: 12th Street SE | K23: 1300 | L23: 400 | N23: 600 | O23: 2 | P23: 4000 | R23: 2500 | S23: =K23*L23+O23*P23+Q23*R23+M23*N23 -> 528000 | T23: =S23*0.1 -> 52800 | U23: =S23*0.07 -> 36960 | V23: =SUM(S23:U23)*0.2 -> 123552 | W23: =SUM(S23:V23) -> 741312 | X23: 477000 | Y23: =W23/X23 -> 1.5541132 | Z23: Single Family | AA23: 1 | AB23: 2 | AC23: 1 | AD23: 2 | AE23: =IF(W23<150000,"3",IF(W23<500000,"2",IF(W23>500000,"1"))) -> 1 | AF23: 2 | AG23: 1 | AH23: 1 | AI23: {=SUM(AA23:AH23/8)} -> 1.375
A24: 20 | B24: CP-124 | C24: TBD-18 | D24: S. Lake Stevens Road MUP Phase III | E24: East Lakeshore Drive S Lake Stevens Rd | F24: 123rd Street SE | G24: Construction of MUP to connect pedestrian generators to the existing trail. | I24: Federal Capital Transportation | S24: 3000000 | T24: =S24*0.1 -> 300000 | U24: 200000 | W24: =SUM(S24:V24) -> 3500000 | X24: 1157000 | Y24: =W24/X24 -> 3.0250648 | Z24: Single Family | AA24: 1 | AB24: 3 | AC24: 2 | AD24: 1 | AE24: =IF(W24<150000,"3",IF(W24<500000,"2",IF(W24>500000,"1"))) -> 1 | AF24: 3 | AG24: 2 | AH24: 1 | AI24: {=SUM(AA24:AH24/8)} -> 1.75
A25: 21 | B25: CP-125 | D25: Vernon Road | E25: 12th Place NE | F25: 15th Street NE | K25: 600 | L25: 400 | N25: 600 | O25: 4 | P25: 4000 | R25: 2500 | S25: =K25*L25+O25*P25+Q25*R25+M25*N25 -> 256000 | T25: =S25*0.1 -> 25600 | U25: =S25*0.07 -> 17920 | V25: =SUM(S25:U25)*0.2 -> 59904 | W25: =SUM(S25:V25) -> 359424 | X25: 266000 | Y25: =W25/X25 -> 1.351218 | Z25: Single Family | AA25: 1 | AB25: 1 | AC25: 1 | AD25: 2 | AE25: =IF(W25<150000,"3",IF(W25<500000,"2",IF(W25>500000,"1"))) -> 2 | AF25: 2 | AG25: 1 | AH25: 1 | AI25: {=SUM(AA25:AH25/8)} -> 1.375 | AL25: Sources
B26: CP-126S | C26: TBD-19 | D26: 20th Street SE | E26: S. Lake Stevens Road | F26: 113th Drive SE | K26: 2000 | L26: 400 | N26: 600 | P26: 4000 | Q26: 8 | R26: 2500 | S26: =K26*L26+O26*P26+Q26*R26+M26*N26 -> 820000 | T26: =S26*0.1 -> 82000 | U26: =S26*0.07 -> 57400 | V26: =SUM(S26:U26)*0.2 -> 191880 | W26: =SUM(S26:V26) -> 1151280 | Z26: Single Family | AA26: 1 | AB26: 3 | AC26: 2 | AD26: 2 | AE26: =IF(W26<150000,"3",IF(W26<500000,"2",IF(W26>500000,"1"))) -> 1 | AF26: 2 | AG26: 1 | AH26: 1 | AI26: {=SUM(AA26:AH26/8)} -> 1.625 | AL26: 2015 Sidewalk Master Plan
B27: CP-127S | C27: TBD-02 | D27: 91st Ave SE | E27: 4th St. SE | F27: Market Street | G27: TBD sidewalk along the east side of 91st Ave SE between 4th and Market. Includes ROW and typical frontage improvements including stormwater. | S27: 760000 | T27: 175000 | W27: =SUM(S27:V27) -> 935000 | Z27: Single Family | AA27: 3 | AB27: 2 | AC27: 2 | AD27: 3 | AE27: =IF(W27<150000,"3",IF(W27<500000,"2",IF(W27>500000,"1"))) -> 1 | AF27: 3 | AG27: 3 | AH27: 1 | AI27: {=SUM(AA27:AH27/8)} -> 2.25 | AL27: Subarea Plans
B28: CP-128S | C28: TBD-03 | D28: 91st Ave SE | E28: 8th Street SE | F28: 4th Street SE | G28: TBD sidewalk along the east side of 91st Ave SE between 8th and 4th. Includes ROW and typical frontage improvements including stormwater. | S28: 405000 | T28: 100000 | W28: =SUM(S28:V28) -> 505000 | Z28: Single Family | AA28: 3 | AB28: 2 | AC28: 2 | AD28: 3 | AE28: =IF(W28<150000,"3",IF(W28<500000,"2",IF(W28>500000,"1"))) -> 1 | AF28: 3 | AG28: 3 | AH28: 1 | AI28: {=SUM(AA28:AH28/8)} -> 2.25 | AL28: 2022 - Local Road Safety Plan (Accident Data)
B29: CP-129S | C29: TBD-13 | D29: 83rd Ave NE | E29: 20th Street SE | F29: 17th Street SE | K29: 850 | L29: 400 | N29: 600 | P29: 4000 | R29: 2500 | S29: =K29*L29+O29*P29+Q29*R29+M29*N29 -> 340000 | T29: =S29*0.1 -> 34000 | U29: =S29*0.07 -> 23800 | V29: =SUM(S29:U29)*0.2 -> 79560 | W29: =SUM(S29:V29) -> 477360 | Z29: Commercial | AA29: 3 | AB29: 2 | AC29: 1 | AD29: 3 | AE29: =IF(W29<150000,"3",IF(W29<500000,"2",IF(W29>500000,"1"))) -> 2 | AF29: 2 | AG29: 1 | AH29: 1 | AI29: {=SUM(AA29:AH29/8)} -> 1.875 | AL29: WSDOT Functional Classification Web Portal
B30: CP-130S | D30: 103rd Ave SE | E30: 32nd Street NE | F30: South Lake Stevens Road | K30: 0 | L30: 400 | N30: 600 | O30: 12 | P30: 4000 | Q30: 4 | R30: 2500 | S30: =K30*L30+O30*P30+Q30*R30+M30*N30 -> 58000 | T30: =S30*0.1 -> 5800 | U30: =S30*0.07 -> 4060 | V30: =SUM(S30:U30)*0.2 -> 13572 | W30: =SUM(S30:V30) -> 81432 | Z30: Single Family | AA30: 1 | AB30: 2 | AC30: 1 | AD30: 3 | AE30: =IF(W30<150000,"3",IF(W30>150000,"2",IF(W30>500000,"1"))) -> 3 | AF30: 2 | AG30: 2 | AH30: 1 | AI30: {=SUM(AA30:AH30/8)} -> 1.875 | AL30: StreetLogix
B31: CP-132S | C31: TBD-08 | D31: 113th Ave NE | E31: 32nd Street NE | F31: 36th Street NE | K31: 0 | L31: 400 | N31: 600 | O31: 11 | P31: 4000 | Q31: 2 | R31: 2500 | S31: =K31*L31+O31*P31+Q31*R31+M31*N31 -> 49000 | T31: =S31*0.1 -> 4900 | U31: =S31*0.07 -> 3430 | V31: =SUM(S31:U31)*0.2 -> 11466 | W31: =SUM(S31:V31) -> 68796 | Z31: Commercial | AA31: 3 | AB31: 1 | AC31: 1 | AD31: 3 | AE31: =IF(W31<150000,"3",IF(W31>150000,"2",IF(W31>500000,"1"))) -> 3 | AF31: 2 | AG31: 2 | AH31: 1 | AI31: {=SUM(AA31:AH31/8)} -> 2
B32: CP-133S | D32: 131st Ave NE | E32: 20th Street NE | F32: Hartford Road | K32: 1800 | L32: 400 | N32: 600 | O32: 2 | P32: 4000 | Q32: 2 | R32: 2500 | S32: =K32*L32+O32*P32+Q32*R32+M32*N32 -> 733000 | T32: =S32*0.1 -> 73300 | U32: =S32*0.07 -> 51310 | V32: =SUM(S32:U32)*0.2 -> 171522 | W32: =SUM(S32:V32) -> 1029132 | Z32: Industrial | AA32: 1 | AB32: 1 | AC32: 1 | AD32: 3 | AE32: =IF(W32<150000,"3",IF(W32<500000,"2",IF(W32>500000,"1"))) -> 1 | AF32: 1 | AG32: 1 | AH32: 1 | AI32: {=SUM(AA32:AH32/8)} -> 1.25
B33: CP-135S | C33: TBD-16 | D33: 99th Ave NE | E33: Sunnycrest Elem. | F33: 30th Street NE | K33: 1300 | L33: 400 | N33: 600 | O33: 2 | P33: 4000 | R33: 2500 | S33: =K33*L33+O33*P33+Q33*R33+M33*N33 -> 528000 | T33: =S33*0.1 -> 52800 | U33: =S33*0.07 -> 36960 | V33: =SUM(S33:U33)*0.2 -> 123552 | W33: =SUM(S33:V33) -> 741312 | Z33: Single Family | AA33: 1 | AB33: 2 | AC33: 1 | AD33: 3 | AE33: =IF(W33<150000,"3",IF(W33<500000,"2",IF(W33>500000,"1"))) -> 1 | AF33: 3 | AG33: 2 | AH33: 1 | AI33: {=SUM(AA33:AH33/8)} -> 1.75
B34: CP-136S | D34: 8th Street SE | E34: 79th Ave SE | F34: 91st Avenue SE | K34: 2500 | L34: 400 | N34: 600 | O34: 4 | P34: 4000 | Q34: 2 | R34: 2500 | S34: =K34*L34+O34*P34+Q34*R34+M34*N34 -> 1021000 | T34: =S34*0.1 -> 102100 | U34: =S34*0.07 -> 71470 | V34: =SUM(S34:U34)*0.2 -> 238914 | W34: =SUM(S34:V34) -> 1433484 | Z34: Single Family | AA34: 1 | AB34: 2 | AC34: 1 | AD34: 2 | AE34: =IF(W34<150000,"3",IF(W34<500000,"2",IF(W34>500000,"1"))) -> 1 | AF34: 2 | AG34: 1 | AH34: 1 | AI34: {=SUM(AA34:AH34/8)} -> 1.375
B35: CP-137S | D35: 30th Street NE | E35: 99th Ave NE | F35: Callow Road | K35: 1200 | L35: 400 | N35: 600 | O35: 4 | P35: 4000 | Q35: 2 | R35: 2500 | S35: =K35*L35+O35*P35+Q35*R35+M35*N35 -> 501000 | T35: =S35*0.1 -> 50100 | U35: =S35*0.07 -> 35070 | V35: =SUM(S35:U35)*0.2 -> 117234 | W35: =SUM(S35:V35) -> 703404 | Z35: Single Family | AA35: 1 | AB35: 1 | AC35: 2 | AD35: 3 | AE35: =IF(W35<150000,"3",IF(W35<500000,"2",IF(W35>500000,"1"))) -> 1 | AF35: 1 | AG35: 1 | AH35: 1 | AI35: {=SUM(AA35:AH35/8)} -> 1.375
B36: CP-138S | D36: Cedar Road | E36: 20th St. NE | F36: 30th Street NE | K36: 3400 | L36: 400 | N36: 600 | O36: 6 | P36: 4000 | Q36: 2 | R36: 2500 | S36: =K36*L36+O36*P36+Q36*R36+M36*N36 -> 1389000 | T36: =S36*0.1 -> 138900 | U36: =S36*0.07 -> 97230 | V36: =SUM(S36:U36)*0.2 -> 325026 | W36: =SUM(S36:V36) -> 1950156 | Z36: Single Family | AA36: 1 | AB36: 1 | AC36: 1 | AD36: 3 | AE36: =IF(W36<150000,"3",IF(W36<500000,"2",IF(W36>500000,"1"))) -> 1 | AF36: 1 | AG36: 1 | AH36: 1 | AI36: {=SUM(AA36:AH36/8)} -> 1.25
B37: CP-139S | C37: TBD-09 | D37: 20th Street NE | E37: Main Street | F37: 131st Ave SE | K37: 0 | L37: 400 | N37: 600 | O37: 4 | P37: 4000 | Q37: 2 | R37: 2500 | S37: =K37*L37+O37*P37+Q37*R37+M37*N37 -> 21000 | T37: =S37*0.1 -> 2100 | U37: =S37*0.07 -> 1470 | V37: =SUM(S37:U37)*0.2 -> 4914 | W37: =SUM(S37:V37) -> 29484 | Z37: Commercial | AA37: 3 | AB37: 3 | AC37: 1 | AD37: 3 | AE37: =IF(W37<150000,"3",IF(W37>150000,"2",IF(W37>500000,"1"))) -> 3 | AF37: 1 | AG37: 1 | AH37: 1 | AI37: {=SUM(AA37:AH37/8)} -> 2
B38: CP-140S | D38: S. Lake Stevens Road MUP Phase II | E38: 18th St SE | F38: SR 9 | G38: Construction of MUP to connect pedestrian generators to the existing trail. | H38: 3000000 | I38: Federal Capital Transportation | S38: 3000000 | T38: =S38*0.1 -> 300000 | U38: 340000 | W38: =SUM(S38:V38) -> 3640000 | Z38: Multi-Family | AA38: 2 | AB38: 2 | AC38: 1 | AD38: 3 | AE38: =IF(W38<150000,"3",IF(W38<500000,"2",IF(W38>500000,"1"))) -> 1 | AF38: 3 | AG38: 2 | AH38: 3 | AI38: {=SUM(AA38:AH38/8)} -> 2.125
B39: CP-141S | C39: TBD-06 | D39: North Lakeshore Drive | E39: Main Street | F39: 123rd Ave NE | G39: TBD sidewalk along one side of N Lakeshore Dr between Main St and 123rd Ave. | S39: 120000 | T39: 30000 | W39: =SUM(S39:V39) -> 150000 | Z39: Commercial | AA39: 3 | AB39: 2 | AC39: 2 | AD39: 2 | AE39: =IF(W39<150000,"3",IF(W39<500000,"2",IF(W39>500000,"1"))) -> 2 | AF39: 2 | AG39: 2 | AH39: 1 | AI39: {=SUM(AA39:AH39/8)} -> 2
B40: CP-142S | C40: TBD-15 | D40: North Lakeshore Drive | E40: 123rd Ave NE | F40: North Lakeshore Swim Beach | K40: 1200 | L40: 400 | N40: 600 | O40: 2 | P40: 4000 | Q40: 2 | R40: 2500 | S40: =K40*L40+O40*P40+Q40*R40+M40*N40 -> 493000 | T40: =S40*0.1 -> 49300 | U40: =S40*0.07 -> 34510 | V40: =SUM(S40:U40)*0.2 -> 115362 | W40: =SUM(S40:V40) -> 692172 | Z40: Commercial | AA40: 3 | AB40: 2 | AC40: 1 | AD40: 2 | AE40: =IF(W40<150000,"3",IF(W40<500000,"2",IF(W40>500000,"1"))) -> 1 | AF40: 3 | AG40: 2 | AH40: 1 | AI40: {=SUM(AA40:AH40/8)} -> 1.875
B41: CP-143S | D41: North Lakeshore Drive | E41: Mitchell Road | F41: 114th Drive NE | K41: 1600 | L41: 400 | N41: 600 | O41: 4 | P41: 4000 | R41: 2500 | S41: =K41*L41+O41*P41+Q41*R41+M41*N41 -> 656000 | T41: =S41*0.1 -> 65600 | U41: =S41*0.07 -> 45920 | V41: =SUM(S41:U41)*0.2 -> 153504 | W41: =SUM(S41:V41) -> 921024 | Z41: Single Family | AA41: 1 | AB41: 2 | AC41: 1 | AD41: 1 | AE41: =IF(W41<150000,"3",IF(W41<500000,"2",IF(W41>500000,"1"))) -> 1 | AF41: 3 | AG41: 1 | AH41: 1 | AI41: {=SUM(AA41:AH41/8)} -> 1.375
B42: CP-144S | D42: 79th Ave SE | E42: 16th Place SE | F42: 14th Street SE | K42: 360 | L42: 400 | N42: 600 | P42: 4000 | Q42: 2 | R42: 2500 | S42: =K42*L42+O42*P42+Q42*R42+M42*N42 -> 149000 | T42: =S42*0.1 -> 14900 | U42: =S42*0.07 -> 10430 | V42: =SUM(S42:U42)*0.2 -> 34866 | W42: =SUM(S42:V42) -> 209196 | Z42: Single Family | AA42: 1 | AB42: 2 | AC42: 1 | AD42: 2 | AE42: =IF(W42<150000,"3",IF(W42<500000,"2",IF(W42>500000,"1"))) -> 2 | AF42: 2 | AG42: 1 | AH42: 1 | AI42: {=SUM(AA42:AH42/8)} -> 1.5
...

Sheet Roadway Projects - All
K8: Minor Arterial | L8: 3200/LF
K9: Collector | L9: 2400/LF
K10: Local Access | L10: 1600/LF
B11: Capital Facilities Plan - Roadways
B12: Project Number | C12: Project Name | D12: Description | E12: Roadway | F12: Start | G12: End | H12: Grant Award | I12: Grant Source | J12: 2022 Budget | K12: Length (LF) | L12: Cost/LF | M12: Project Planning | N12: PE | O12: ROW | P12: Construction | Q12: Contingency | R12: Total Cost | S12: Highest Land Use Type Within 1/2 Mile | T12: Roadway Type | U12: Accident Data | V12: Facility within 1/4 Mile | W12: Facility within 1/2 mile | X12: Cost | Y12: Opportunity | Z12: Grant Eligibility | AA12: Dedicated Funding | AB12: Average Score | AD12: Roadway - Evaluation Criteria
B13: RD-100 | C13: 79th Ave SE Access Road | D13: Construct new roadway including 7' bike lane, two 11' travel lanes, 5' landscape strips and 5' sidewalks for through road to Cavalero Mid-High School | E13: 79th Ave SE Access Road | F13: 20th St. NE | G13: 83rd Ave SE | K13: =1250*0.75 -> 937.5 | L13: 2400 | M13: =P13*0.01 -> 22500 | N13: =P13*0.1 -> 225000 | O13: =P13*0.07 -> 157500 | P13: =K13*L13 -> 2250000 | Q13: =SUM(M13:P13)*0.2 -> 531000 | R13: =SUM(M13:Q13) -> 3186000 | S13: 3 | T13: 2 | U13: 1 | V13: 3 | W13: 2 | X13: 2 | Y13: 3 | Z13: 3 | AA13: 3 | AB13: {=SUM(T13:AA13/9)} -> 2.1111111 | AD13: Priority | AE13: Highest Land Use Type Within 1/2 Mile | AF13: Roadway Type | AG13: Accident Data | AH13: Facility within 1/4 Mile | AI13: Facility within 1/2 mile | AJ13: Cost | AK13: Opportunity | AL13: Grant Eligibility | AM13: Dedicated Funding
B14: RD-101 | C14: Main Street Improvements (16th St NE to 20th St NE) | D14: Multi-use path, street frontage improvements along Main Street between 16th St to 20th St. | E14: Main Street | F14: 16th Street NE | G14: 20th Street NE | H14: 1959620 | I14: PSRC (Federal) | K14: 1600 | L14: 3200 | M14: =P14*0.01 -> 51200 | N14: =P14*0.1 -> 512000 | O14: =P14*0.07 -> 358400 | P14: =K14*L14 -> 5120000 | Q14: =SUM(M14:P14)*0.2 -> 1208320 | R14: =SUM(M14:Q14) -> 7249920 | S14: 3 | T14: 2 | U14: 1 | V14: 3 | W14: 2 | X14: 1 | Y14: 3 | Z14: 3 | AA14: 2 | AB14: {=SUM(T14:AA14/9)} -> 1.8888889 | AD14: High = 3 | AE14: Commercial | AF14: Minor Arterial | AG14: Fatal Accident | AH14: Adjacent to a medical office | AJ14: <$1,000,000 | AK14: Public Support is Strong | AL14: Eligible for more than two grants | AM14: Full Funding
B15: RD-113 | C15: 20th St NE and Main Street Improvements | D15: Construct roundabout and frontage improvements per the downtown subarea plan. | E15: 20th Street NE | F15: Main Street | G15: Main Street | H15: 2500000 | I15: Federal Earmark | N15: 140000 | O15: 60000 | P15: 3000000 | R15: =SUM(M15:Q15) -> 3200000 | S15: 3 | T15: 2 | U15: 1 | V15: 3 | W15: 2 | X15: 1 | Y15: 3 | Z15: 3 | AA15: 2 | AB15: {=SUM(T15:AA15/9)} -> 1.8888889 | AF15: Collisions involving pedestrians | AG15: Vehicle on Ped Accident | AH15: Adjacent to services for the disabled | AK15: Political Support is Strong
B16: RD-102I | C16: 91st Ave NE Commercial Revitalization Phase I | D16: Upgrade road to minor arterial road standard. Potential for roundabout at midblock for circulation into commercial areas. | E16: 91st Street NE | F16: Market Place | G16: SR 204 | N16: =Table3[[#This Row],[Construction]]*0.1 -> 350000 | P16: 3500000 | R16: =SUM(M16:Q16) -> 3850000 | S16: 3 | T16: 2 | U16: 3 | V16: 3 | W16: 2 | X16: 1 | Y16: 2 | Z16: 3 | AA16: 1 | AB16: {=SUM(T16:AA16/9)} -> 1.8888889 | AF16: Streets with highway interchange | AH16: Adjacent to a library
B17: RD-102II | C17: 91st Ave NE Commercial Revitalization | D17: Upgrade road to minor arterial road standard. Potential for roundabout at midblock for circulation into commercial areas. | E17: 91st Street NE | F17: SR 204 | G17: Frontier Circle | N17: =Table3[[#This Row],[Construction]]*0.1 -> 100000 | P17: 1000000 | R17: =SUM(M17:Q17) -> 1100000 | S17: 3 | T17: 2 | U17: 3 | V17: 3 | W17: 2 | X17: 1 | Y17: 2 | Z17: 3 | AA17: 1 | AB17: {=SUM(T17:AA17/9)} -> 1.8888889 | AH17: Adjacent to a senior center or senior housing
B18: RD-103 | C18: 99th Ave NE - Boulevard | D18: Upgrade road to minor arterial road standard including multi-use path or sidewalk with 7' bike lane, 11' travel lanes and 12' center lane with landscape islands. Potential for roundabout at midblock for circulation into commercial areas | E18: 99th Ave NE | F18: Market Place | G18: 4th Street NE | K18: 1300 | L18: 3200 | M18: =P18*0.01 -> 41600 | N18: =P18*0.1 -> 416000 | O18: =P18*0.07 -> 291200 | P18: =K18*L18 -> 4160000 | Q18: =SUM(M18:P18)*0.2 -> 981760 | R18: =SUM(M18:Q18) -> 5890560 | S18: 3 | T18: 2 | U18: 1 | V18: 3 | W18: 2 | X18: 1 | Y18: 1 | Z18: 3 | AA18: 1 | AB18: {=SUM(T18:AA18/9)} -> 1.5555556 | AH18: Adjacent to a school
B19: RD-104 | C19: Grade Road - Boulevard | D19: Upgrade road to minor arterial road standard including multi-use path or sidewalk with 7' bike lane, 11' travel lanes and 12' center lane with landscape islands. | E19: Grade Road | F19: Hartford | G19: Catherine Drive | K19: 3500 | L19: 3200 | M19: =P19*0.01 -> 112000 | N19: =P19*0.1 -> 1120000 | O19: =P19*0.07 -> 784000 | P19: =K19*L19 -> 11200000 | Q19: =SUM(M19:P19)*0.2 -> 2643200 | R19: =SUM(M19:Q19) -> 15859200 | S19: 3 | T19: 2 | U19: 1 | V19: 3 | W19: 2 | X19: 1 | Y19: 1 | Z19: 3 | AA19: 1 | AB19: {=SUM(T19:AA19/9)} -> 1.5555556 | AH19: Adjacent to a high use transit stop
B20: RD-105 | C20: 125th Ave NE/18th St NE/20th St NE Downtown Roadway Improvements | D20: Upgrade road to two 10' travel lanes, 8' parking on both sides, 5' planters and 5' sidewalks. | E20: 125th Ave NE/18th St NE/20th St | F20: Main Street/18th St. NE Intersection | G20: Main Street/20th St. NE Intersection | K20: 1230 | L20: 2400 | M20: =P20*0.01 -> 29520 | N20: =P20*0.1 -> 295200 | O20: =P20*0.07 -> 206640 | P20: =K20*L20 -> 2952000 | Q20: =SUM(M20:P20)*0.2 -> 696672 | R20: =SUM(M20:Q20) -> 4180032 | S20: 3 | T20: 1 | U20: 1 | V20: 3 | W20: 2 | X20: 2 | Y20: 1 | Z20: 3 | AA20: 1 | AB20: {=SUM(T20:AA20/9)} -> 1.5555556
B21: RD-106 | C21: 79th Ave SE & 8th St SE Intersection Improvements | D21: Improve the intersection at 79th Ave SE and 8th Street SE. Implement safety improvements at adjacent intersections along corridor. | E21: 79th Ave SE/8th St. SE Intersection | F21: 10th St SE | G21: 83rd Ave SE | J21: 100000 | N21: =P21*0.1 -> 50000 | O21: =P21*0.07 -> 35000 | P21: 500000 | Q21: 50000 | R21: =SUM(M21:Q21) -> 635000 | S21: 1 | T21: 2 | U21: 1 | V21: 1 | W21: 0 | X21: 3 | Y21: 3 | Z21: 2 | AA21: 1 | AB21: {=SUM(T21:AA21/9)} -> 1.4444444 | AD21: Medium = 2 | AE21: Mixed Use | AF21: Major Collector | AG21: Serious Injury Accident | AH21: Adjacent to a public office | AI21: Adjacent to a medical office | AJ21: 1,000,001- 5,000,000 | AK21: Public or Political Support Strong | AL21: Eligible for one grant | AM21: >50% Funded
B22: RD-107 | C22: Madrona Drive | D22: Convert half road to reduced standard local access road section including two 10' travel lanes and a sidewalk on a single side of the road. | E22: Madrona Drive | F22: Lake View Drive | G22: End of Road | K22: 470 | L22: 1600 | M22: =P22*0.01 -> 7520 | N22: =P22*0.1 -> 75200 | O22: =P22*0.07 -> 52640 | P22: =K22*L22 -> 752000 | Q22: =SUM(M22:P22)*0.2 -> 177472 | R22: =SUM(M22:Q22) -> 1064832 | S22: 1 | T22: 1 | U22: 1 | V22: 2 | W22: 1 | X22: 2 | Y22: 1 | Z22: 1 | AA22: 1 | AB22: {=SUM(T22:AA22/9)} -> 1.1111111 | AE22: Multi-Family | AF22: Minor Collector | AH22: Adjacent to a park | AI22: Adjacent to services to the disabled
B23: RD-108 | C23: Alder Road | D23: Convert half road to reduced standard local access road section including two 10' travel lanes and a sidewalk on a single side of the road. | E23: Alder Road | F23: Lake View Drive | G23: End of Road | K23: 700 | L23: 1600 | M23: =P23*0.01 -> 11200 | N23: =P23*0.1 -> 112000 | O23: =P23*0.07 -> 78400 | P23: =K23*L23 -> 1120000 | Q23: =SUM(M23:P23)*0.2 -> 264320 | R23: =SUM(M23:Q23) -> 1585920 | S23: 1 | T23: 1 | U23: 1 | V23: 2 | W23: 1 | X23: 2 | Y23: 1 | Z23: 1 | AA23: 1 | AB23: {=SUM(T23:AA23/9)} -> 1.1111111 | AH23: Connects or completes street(s) | AI23: Adjacent to a library
B24: RD-109 | C24: 101st Ave NE | D24: Convert half road to reduced standard local access road section including two 10' travel lanes and a sidewalk on a single side of the road. | E24: 101st Ave NE | F24: Lundeen Parkway | G24: 30th Street NE | K24: 2100 | L24: 1600 | M24: =P24*0.01 -> 33600 | N24: =P24*0.1 -> 336000 | O24: =P24*0.07 -> 235200 | P24: =K24*L24 -> 3360000 | Q24: =SUM(M24:P24)*0.2 -> 792960 | R24: =SUM(M24:Q24) -> 4757760 | S24: 1 | T24: 1 | U24: 1 | V24: 2 | W24: 1 | X24: 2 | Y24: 1 | Z24: 1 | AA24: 1 | AB24: {=SUM(T24:AA24/9)} -> 1.1111111 | AI24: Adjacent to a senior center or senior housing
B25: RD-110 | C25: 99th/20th U-turn Channelization | D25: Rechannelize 20th Street SE to allow for U-turns at the intersection of 20th Street SE and 99th Ave SE. | E25: 20th Street SE | F25: 99th Ave SE | G25: 99th Ave SE | J25: 30000 | K25: 100 | L25: 0 | N25: 5000 | P25: 25000 | R25: =SUM(M25:Q25) -> 30000 | S25: 3 | T25: 3 | U25: 3 | V25: 2 | W25: 1 | X25: 3 | Y25: 3 | Z25: 1 | AA25: 3 | AB25: {=SUM(T25:AA25/9)} -> 2.1111111 | AI25: Adjacent to a school
B26: RD-111 | C26: 12th St. SE/87th Ave SE Road Realignment | D26: The intersection at 87th Street SE and 12th Street SE is not aligned to provide adequate sight distances for vehicles. Project will realign the intersection and construct additional roadway surface. | J26: 50000 | K26: 200 | L26: 1600 | M26: =P26*0.01 -> 3200 | N26: 10000 | O26: =P26*0.07 -> 22400 | P26: =Table3[[#This Row],[Length (LF)]]*Table3[[#This Row],[Cost/LF]] -> 320000 | Q26: =SUM(M26:P26)*0.2 -> 71120 | R26: =SUM(M26:Q26) -> 426720 | S26: 1 | T26: 1 | U26: 1 | V26: 1 | W26: 1 | X26: 3 | Y26: 3 | Z26: 1 | AA26: 3 | AB26: {=SUM(T26:AA26/9)} -> 1.5555556
B27: RD-112 | C27: 91st Ave SE/24th Street SE/S. Lake Stevens Road | D27: Construction of minor arterial south of 20th Street SE that provides an additional connection to SR 9. | E27: 91st Ave SE | F27: 24th St. SE | G27: 20th St. SE | H27: 3000000 | I27: TIB | J27: 15500000 | R27: =SUM(M27:Q27) -> 0 | S27: 3 | T27: 3 | U27: 1 | V27: 2 | W27: 1 | X27: 1 | Y27: 3 | Z27: 3 | AA27: 3 | AB27: {=SUM(T27:AA27/9)} -> 1.8888889 | AD27: Low = 1 | AE27: Single Family | AF27: Neighborhood | AG27: Other | AI27: Adjacent to a high use transit stop | AJ27: >5,000,001 | AK27: Support Not Known/Not Supportive | AL27: Not eligible for grants | AM27: <50% Funded
B28: RD-113 | C28: Mill Spur Traffic Calming | D28: A study and implementation of traffic calming at Mill Spur
B29: RD-114 | C29: Lundeen Parkway Splitter Island Concrete Replacement | D29: The rock-lined approaches at the Lundeen Parkway roundabouts requires that the PW crew perform regular and time-consuming maintenances to ensure weeds do not grow.
B30: RD-115 | C30: Replace Speed Feedback Signs | D30: Current speed feedback signs in the City are not supported from the manufacture and the majority of them are failing and need to be replaced. Speed feedback signs have been proven to help reduce traffic speeds.
B31: RD-116 | C31: EDDS Update | D31: Update Chapter 5-9 and publish
B32: RD-117 | C32: Traffic Safety Cameras Program and Equipment | D32: City Council has authorized the ordinance to install traffic safety cameras. This ordinance grants the ability to put into place a program. The budget request reflects the need to do a traffic analysis in the City in the locations proposed to install the cameras. This budget amount also includes the installation of the cameras. _x000D_ _x000D_ Each camera is approximately $65,000 per camera. The goal is to install 2 cameras each in 3 locations. The additional budget will cover consultant costs to perform the traffic analysis and justification required to install the cameras.
D33: Total | R33: =SUM(R13:R27) -> 53015944 | AE33: Industrial | AI33: Adjacent to a public office
AI34: Adjacent to a park
AI35: Connects or completes street(s)
AD37: Adjacent is within 1/4 mile

Sheet Parks - All
B2: Capital Facilities Plan - Parks | AB2: Parks - Scoring Criteria
A3: Project Number | B3: Project Number2 | C3: Project Name | D3: Location | E3: Description | F3: Grant Award | G3: Grant Source | H3: 2022 Budget | I3: Construction Estimate | J3: A&E | K3: ROW/Property | L3: Contingency | M3: Construction Management | N3: Total Cost | O3: Zoning | P3: Zoning Score | Q3: Park Service Type/ Classification | R3: Park Distribution | S3: Park Amenities | T3: Cost | U3: Opportunity | V3: Partnership Opportunity | W3: Grant Eligibility | X3: Dedicated Funding | Y3: Average Score | AB3: Priority | AC3: Zoning | AD3: Park Service Type/Classification | AE3: Park Distribution | AF3: Park Amenities | AG3: Cost | AH3: Opportunity | AI3: Partnership Opportunity | AJ3: Grant Eligibility | AK3: Dedicated Funding
B4: PR-100 | C4: Frontier Heights Phase II | D4: 48.005875, -122.111164 | E4: Design and construction of a multiuse athletic field, drainage and parking lot improvements and pickleball courts. | F4: 0 | G4: WWRP ($500K), YAF ($350K) | H4: 225000 | I4: 3040314 | J4: =I4*0.1 -> 304031.4 | K4: 0 | L4: =SUM(I4*0.1) -> 304031.4 | M4: =I4*0.07 -> 212821.98 | N4: =SUM(I4:M4) -> 3861198.8 | O4: Public/Semi-Public | P4: 3 | Q4: 3 | R4: 3 | S4: 3 | T4: =IF(N4<150000,"3",IF(N4<500000,"2",IF(N4>500000,"1"))) -> 1 | U4: 3 | V4: 2 | W4: 3 | X4: 2 | Y4: =SUM(P4:X4)/8 -> 2.75 | AB4: High = 3 | AC4: Multi-Family | AD4: Community Park (>10 acres) | AE4: Community park that fills 2.5 mile distribution gap to residential zone | AF4: Playfields | AG4: <$150,000 | AH4: Public Support is Strong and Political Support is Strong | AI4: Agreement in place | AJ4: Eligible for more than two grants | AK4: Full Funding
B5: PR-101 | C5: Mill Spur Concession/Restroom | E5: Construct a restroom and concession building on Mill Spur | H5: 200000 | I5: 180000 | J5: =I5*0.1 -> 18000 | L5: =SUM(I5*0.1) -> 18000 | M5: =I5*0.07 -> 12600 | N5: =SUM(I5:M5) -> 228600 | O5: Public/Semi-Public | P5: 3 | Q5: 2 | R5: 3 | S5: 3 | T5: =IF(N5<150000,"3",IF(N5<500000,"2",IF(N5>500000,"1"))) -> 2 | U5: 3 | V5: 3 | W5: 3 | X5: 2 | Y5: =SUM(P5:X5)/8 -> 2.75 | AD5: Trail >1 Mile | AE5: Neighborhood park that fills 1 mile distribution gap to residential zone | AF5: Community Center
B6: PR-102 | C6: Eagle Ridge Park Phase II | D6: 48.018446, -122.106445 | E6: Design and construct an amphitheater, playground, restrooms, parking and frontage improvements. | F6: 428000 | G6: RCO | H6: 995200 | I6: 3200000 | J6: 500000 | K6: 0 | L6: =SUM(I6*0.1) -> 320000 | M6: =I6*0.07 -> 224000 | N6: =SUM(I6:M6) -> 4244000 | O6: Public/Semi-Public | P6: 2 | Q6: 3 | R6: 3 | S6: 3 | T6: =IF(N6<150000,"3",IF(N6<500000,"2",IF(N6>500000,"1"))) -> 1 | U6: 3 | V6: 2 | W6: 3 | X6: 2 | Y6: =SUM(P6:X6)/8 -> 2.625 | AC6: Mixed Use | AE6: Mini-park that fills 0.5 mile distribution gap to residential areas | AF6: Playgrounds and Restroom
B7: PR-103 | C7: North Cove Dock Boat Slips | E7: Add up to six boat slips to the west side of the pier. | F7: 116245 | G7: RCO | H7: =F7 -> 116245 | I7: 100000 | J7: =I7*0.1 -> 10000 | K7: =I7*0.07 -> 7000 | L7: =SUM(I7*0.1) -> 10000 | M7: =I7*0.07 -> 7000 | N7: =SUM(I7:M7) -> 134000 | O7: Multi Family | P7: 3 | Q7: 2 | R7: 3 | S7: 3 | T7: =IF(N7<150000,"3",IF(N7<500000,"2",IF(N7>500000,"1"))) -> 3 | U7: 3 | V7: 2 | W7: 2 | X7: 3 | Y7: =SUM(P7:X7)/8 -> 2.625 | AF7: Dock/Pier and Swim Beach
B8: PR-104 | C8: Cedarwood Recreation Center | E8: Construct a community center/recreation space by renovating an existing building that previously served this purpose. | H8: 100000 | I8: 4950000 | J8: 1031073 | K8: 340000 | L8: =SUM(I8*0.1) -> 495000 | M8: =I8*0.07 -> 346500 | N8: =SUM(I8:M8) -> 7162573 | O8: Public/Semi-Public | P8: 3 | Q8: 3 | R8: 2 | S8: 3 | T8: =IF(N8<150000,"3",IF(N8<500000,"2",IF(N8>500000,"1"))) -> 1 | U8: 3 | V8: 3 | W8: 2 | X8: 1 | Y8: =SUM(P8:X8)/8 -> 2.5
B9: PR-105 | C9: North Cove Pedestrian Bridge | E9: Construct abutments and place previously purchased pedestrian bridge over the Lake Stevens outlet channel between North Cove Park and North Lakeshore Drive. | H9: 50000 | I9: 50000 | J9: =I9*0.1 -> 5000 | K9: =I9*0.07 -> 3500 | L9: =SUM(I9*0.1) -> 5000 | M9: =I9*0.07 -> 3500 | N9: =SUM(I9:M9) -> 67000 | O9: Commercial | P9: 1 | Q9: 2 | R9: 3 | S9: 3 | T9: =IF(N9<150000,"3",IF(N9<500000,"2",IF(N9>500000,"1"))) -> 3 | U9: 1 | V9: 3 | W9: 3 | X9: 2 | Y9: =SUM(P9:X9)/8 -> 2.25
B10: PR-106 | C10: Sunset Park Phase II | E10: Pave parking lot, drainage improvements, ADA path with overlook deck. | G10: RCO (Pending) | H10: 0 | I10: 0 | J10: =I10*0.1 -> 0 | K10: 0 | L10: =SUM(I10*0.1) -> 0 | M10: =I10*0.07 -> 0 | N10: =SUM(I10:M10) -> 0 | O10: Single Family | P10: 2 | Q10: 1 | R10: 3 | S10: 3 | T10: =IF(N10<150000,"3",IF(N10<500000,"2",IF(N10>500000,"1"))) -> 3 | U10: 3 | V10: 3 | W10: 2 | X10: 2 | Y10: =SUM(P10:X10)/8 -> 2.375
B11: PR-107 | C11: North Cove Docks @ Boat Launch | E11: Repair/Replace boat launch dock and slips. | H11: 0 | I11: 2300000 | J11: =I11*0.1 -> 230000 | K11: 0 | L11: =SUM(I11*0.1) -> 230000 | M11: =I11*0.07 -> 161000 | N11: =SUM(I11:M11) -> 2921000 | O11: Commercial | P11: 1 | Q11: 2 | R11: 3 | S11: 3 | T11: =IF(N11<150000,"3",IF(N11<500000,"2",IF(N11>500000,"1"))) -> 1 | U11: 3 | V11: 3 | W11: 3 | X11: 1 | Y11: =SUM(P11:X11)/8 -> 2.375
B12: PR-108 | C12: Frontier Heights Phase III | D12: 48.005875, -122.111164 | E12: Construction of a labyrinth exercise equipment and a sensory garden with associated pedestrian connections. | H12: 0 | I12: 150000 | J12: =I12*0.1 -> 15000 | K12: 0 | L12: =SUM(I12*0.1) -> 15000 | M12: =I12*0.07 -> 10500 | N12: =SUM(I12:M12) -> 190500 | O12: Public/Semi-Public | P12: 3 | Q12: 3 | R12: 3 | S12: 3 | T12: =IF(N12<150000,"3",IF(N12<500000,"2",IF(N12>500000,"1"))) -> 2 | U12: 3 | V12: 1 | W12: 1 | X12: 1 | Y12: =SUM(P12:X12)/8 -> 2.25 | AB12: Medium = 2 | AC12: Single Family | AD12: Neighborhood Park (<10 acres) | AE12: Community park that fills <2.5 mile to 1 mile distribution gap | AF12: Trail/Pathway (>0.5 miles) | AG12: $150,001 to $500,000 | AH12: Public or Political Support Strong | AI12: Agreement is pending with support | AJ12: Eligible for one grant | AK12: >50% Funded
B13: PR-109 | C13: 20th St. SE Ballfields/Powerline Trail Phase I | D13: 47.979151, -122.113690 | E13: Construct paved parking lot adjacent to 20th Street SE and 3,800 linear feet of multi-use path between 20th Street SE and 8th Street SE. | G13: Pandemic Recovery (500K), Park Mitigation (1.1 million) | H13: 475000 | I13: =125000+3800*(300) -> 1265000 | J13: =I13*0.1 -> 126500 | K13: =I13*0.01 -> 12650 | L13: =SUM(I13*0.12) -> 151800 | M13: =I13*0.07 -> 88550 | N13: =SUM(I13:M13) -> 1644500 | O13: Single Family | P13: 2 | Q13: 2 | R13: 3 | S13: 3 | T13: =IF(N13<150000,"3",IF(N13<500000,"2",IF(N13>500000,"1"))) -> 1 | U13: 2 | V13: 2 | W13: 2 | X13: 2 | Y13: =SUM(P13:X13)/8 -> 2.25 | AD13: Trail >0.5 Mile | AE13: Neighborhood park that fills <1 to 0.5 mile distribution gap to residential zone
B14: PR-110 | C14: Eagle Ridge Property Acquisition | E14: Acquire residential property adjacent to Eagle Ridge Park | H14: 0 | I14: 150000 | J14: 45000 | K14: 700000 | L14: =SUM(I14*0.1) -> 15000 | M14: =I14*0.07 -> 10500 | N14: =SUM(I14:M14) -> 920500 | O14: Single Family | P14: 2 | Q14: 3 | R14: 3 | S14: 3 | T14: =IF(N14<150000,"3",IF(N14<500000,"2",IF(N14>500000,"1"))) -> 1 | U14: 3 | V14: 2 | W14: 1 | X14: 1 | Y14: =SUM(P14:X14)/8 -> 2.25 | AF14: Swim Beach
B15: PR-111 | C15: Sunset Park Phase I | E15: Stabilize dock and shoreline. Improve landscaping. | F15: 5000 | G15: County Grant | H15: 0 | I15: 0 | J15: 0 | L15: =SUM(I15*0.1) -> 0 | M15: =I15*0.07 -> 0 | N15: =SUM(I15:M15) -> 0 | O15: Single Family | P15: 2 | Q15: 1 | R15: 3 | S15: 3 | T15: =IF(N15<150000,"3",IF(N15<500000,"2",IF(N15>500000,"1"))) -> 3 | U15: 3 | V15: 3 | W15: 1 | X15: 1 | Y15: =SUM(P15:X15)/8 -> 2.125
B16: PR-112 | C16: Neighborhood Park Acquisition | D16: Varies | E16: Identify locations for and acquire lands for a neighborhood level park in the southeastern part of the City. | H16: 0 | I16: 750000 | J16: =I16*0.1 -> 75000 | K16: 1000000 | L16: =SUM(I16*0.1) -> 75000 | M16: =I16*0.07 -> 52500 | N16: =SUM(I16:M16) -> 1952500 | O16: Public/Semi-Public | P16: 2 | Q16: 2 | R16: 3 | S16: 3 | T16: =IF(N16<150000,"3",IF(N16<500000,"2",IF(N16>500000,"1"))) -> 1 | U16: 3 | V16: 1 | W16: 2 | X16: 1 | Y16: =SUM(P16:X16)/8 -> 2.125 | AB16: Low = 1 | AC16: Commercial | AD16: Mini-Park (<1 acre) | AE16: Community park that fills <1 mile distribution gap | AF16: View Corridor | AG16: >$500,000 | AH16: Support Not Known/Not Supportive | AI16: No agreement in place or pending | AJ16: Eligibility Unknown | AK16: <50% Funded
B17: PR-113 | C17: Davies Beach Pier Restoration | E17: Restore the pier with new decking, piling repairs as needed, add three boat slips with lifts for emergency responder boats. Pier area is 5,500 sq. ft. | H17: 50000 | I17: 280000 | J17: =I17*0.1 -> 28000 | K17: =I17*0.07 -> 19600 | L17: =SUM(I17*0.1) -> 28000 | M17: =I17*0.07 -> 19600 | N17: =SUM(I17:M17) -> 375200 | O17: Public/Semi-Public | P17: 2 | Q17: 2 | R17: 2 | S17: 3 | T17: =IF(N17<150000,"3",IF(N17<500000,"2",IF(N17>500000,"1"))) -> 2 | U17: 2 | V17: 3 | W17: 1 | X17: 1 | Y17: =SUM(P17:X17)/8 -> 2 | AC17: Industrial | AD17: Open Space | AE17: Neighborhood park that fills <0.5 mile distribution gap to residential zone | AF17: Open Space
B18: PR-114 | C18: Future - Pump Track and Climbing Wall | E18: Improve trails, construct a pump track and climbing walls. | G18: Park Mitigation | H18: 25000 | I18: 1000000 | J18: =I18*0.1 -> 100000 | K18: =I18*0.07 -> 70000 | L18: =SUM(I18*0.1) -> 100000 | M18: =I18*0.07 -> 70000 | N18: =SUM(I18:M18) -> 1340000 | O18: Public/Semi-Public | P18: 2 | Q18: 2 | R18: 3 | S18: 2 | T18: =IF(N18<150000,"3",IF(N18<500000,"2",IF(N18>500000,"1"))) -> 1 | U18: 3 | V18: 1 | W18: 2 | X18: 1 | Y18: =SUM(P18:X18)/8 -> 2 | AD18: Trail <0.5 Mile | AE18: Mini-park that fills <0.5 mile distribution gap to residential areas | AF18: Trail/Pathway (<0.5 miles)
B19: PR-115 | C19: Bayview Trail Phase 2 | E19: Construct 4,000 linear feet of multi-use path between 8th St. SE and Market Place. | H19: 0 | I19: =300*3800 -> 1140000 | J19: =I19*0.1 -> 114000 | K19: 50000 | L19: =SUM(I19*0.1) -> 114000 | M19: =I19*0.07 -> 79800 | N19: =SUM(I19:M19) -> 1497800 | O19: Multi Family | P19: 3 | Q19: 3 | R19: 1 | S19: 2 | T19: =IF(N19<150000,"3",IF(N19<500000,"2",IF(N19>500000,"1"))) -> 1 | U19: 2 | V19: 1 | W19: 1 | X19: 1 | Y19: =SUM(P19:X19)/8 -> 1.75
B20: PR-116 | C20: Bonneville Ballfields | E20: Replace the field surface and renovate the athletic field amenities. | F20: - | H20: 0 | I20: 750000 | J20: =I20*0.1 -> 75000 | K20: 0 | L20: =SUM(I20*0.1) -> 75000 | M20: =I20*0.07 -> 52500 | N20: =SUM(I20:M20) -> 952500 | O20: Single Family | P20: 2 | Q20: 2 | R20: 2 | S20: 3 | T20: =IF(N20<150000,"3",IF(N20<500000,"2",IF(N20>500000,"1"))) -> 1 | U20: 1 | V20: 1 | W20: 1 | X20: 1 | Y20: =SUM(P20:X20)/8 -> 1.625
B21: PR-117 | C21: Mini-Park Restoration | E21: Restoration program for mini-parks throughout the City. Mini-parks typically have playgrounds that need to be replaced or repaired. This is recurring annual funding. | I21: 75000 | J21: =I21*0.1 -> 7500 | K21: 0 | L21: =SUM(I21*0.1) -> 7500 | M21: =I21*0.07 -> 5250 | N21: =SUM(I21:M21) -> 95250 | O21: Public/Semi-Public | P21: 2 | Q21: 1 | R21: 2 | S21: 3 | T21: =IF(N21<150000,"3",IF(N21<500000,"2",IF(N21>500000,"1"))) -> 3 | U21: 2 | V21: 1 | W21: 1 | X21: 1 | Y21: =SUM(P21:X21)/8 -> 1.625
B22: R-1148 | C22: North Cove Parking Lot | E22: Remove administrative buildings and construct new parking lot. | I22: 450000 | J22: =I22*0.1 -> 45000 | L22: =SUM(I22*0.1) -> 45000 | M22: =I22*0.07 -> 31500 | N22: =SUM(I22:M22) -> 571500 | O22: Public/Semi-Public | T22: =IF(N22<150000,"3",IF(N22<500000,"2",IF(N22>500000,"1"))) -> 1 | Y22: =SUM(P22:X22)/8 -> 0
B23: R-119 | C23: Bayview Trail Phase 1a | E23: Construct 1,000 linear feet of multi-use trail from 12th St. SE and 8th St. SE | J23: =I23*0.1 -> 0 | L23: =SUM(I23*0.1) -> 0 | M23: =I23*0.07 -> 0 | N23: 400000 | O23: Public/Semi-Public | T23: =IF(N23<150000,"3",IF(N23<500000,"2",IF(N23>500000,"1"))) -> 2 | Y23: =SUM(P23:X23)/8 -> 0
B24: R-120 | C24: Bayview Trail Phase 3 | E24: Construct 3200 linear feet of multi-use trail from Market Place to Frontier CIrcle | I24: 1000000 | J24: 100000 | K24: 200000 | L24: =SUM(I24*0.1) -> 100000 | M24: =I24*0.07 -> 70000 | N24: =SUM(I24:M24) -> 1470000 | T24: =IF(N24<150000,"3",IF(N24<500000,"2",IF(N24>500000,"1"))) -> 1
B25: R-121 | C25: NC Playground Concrete Seat Wall Adjustment | E25: This project consists of hiring a contractor to cut a portion of the vertical concrete wall and patching the ground around it. | J25: =I25*0.1 -> 0 | L25: =SUM(I25*0.1) -> 0 | M25: =I25*0.07 -> 0 | N25: =SUM(I25:M25) -> 0 | T25: =IF(N25<150000,"3",IF(N25<500000,"2",IF(N25>500000,"1"))) -> 3 | Y25: =SUM(P25:X25)/8 -> 0
B26: R-122 | C26: WeatherTrak Irrigation System Addition | E26: 4 parks - North Cove, Davies, Lundeen and Oak. This is a smart irrigation controller that uses weather data to adjust watering schedules | J26: =I26*0.1 -> 0 | L26: =SUM(I26*0.1) -> 0 | M26: =I26*0.07 -> 0 | N26: =SUM(I26:M26) -> 0 | T26: =IF(N26<150000,"3",IF(N26<500000,"2",IF(N26>500000,"1"))) -> 3 | Y26: =SUM(P26:X26)/8 -> 0
B27: R-123 | C27: Extend Railing - NC Observation Deck | E27: The North Cove Observation Deck has a railing with cable system around half of it. A step will be added to the west side (grass hill) of the observation deck and continue the fencing around the North side of the Observation Deck. | J27: =I27*0.1 -> 0 | L27: =SUM(I27*0.1) -> 0 | M27: =I27*0.07 -> 0 | N27: =SUM(I27:M27) -> 0 | T27: =IF(N27<150000,"3",IF(N27<500000,"2",IF(N27>500000,"1"))) -> 3 | Y27: =SUM(P27:X27)/8 -> 0
B28: R-124 | C28: Utility/Storage Building - Cavalero | E28: A 10x20 concrete block building at Cavalero Park for storage of materials and supplies needed for parks maintenance | J28: =I28*0.1 -> 0 | L28: =SUM(I28*0.1) -> 0 | M28: =I28*0.07 -> 0 | N28: =SUM(I28:M28) -> 0 | T28: =IF(N28<150000,"3",IF(N28<500000,"2",IF(N28>500000,"1"))) -> 3 | Y28: =SUM(P28:X28)/8 -> 0
B29: R-125 | C29: Cavalero Community/Sports Center - Design | E29: Design and Engineering. 80-100k Community & Sports Center - Partnership with TBD | J29: =I29*0.1 -> 0 | L29: =SUM(I29*0.1) -> 0 | M29: =I29*0.07 -> 0 | N29: =SUM(I29:M29) -> 0 | T29: =IF(N29<150000,"3",IF(N29<500000,"2",IF(N29>500000,"1"))) -> 3 | Y29: =SUM(P29:X29)/8 -> 0
B30: R-126 | C30: Cavalero Community/Sports Center - Design | E30: Design and Engineering. 80-100k Community & Sports Center - Partnership with TBD | J30: =I30*0.1 -> 0 | L30: =SUM(I30*0.1) -> 0 | M30: =I30*0.07 -> 0 | N30: =SUM(I30:M30) -> 0 | T30: =IF(N30<150000,"3",IF(N30<500000,"2",IF(N30>500000,"1"))) -> 3 | Y30: =SUM(P30:X30)/8 -> 0
B31: R-127 | C31: Water Deduct Meter Installation | E31: Irrigation or water lines may need to be modified to reroute water. Each deduct meter will cost approximately $1300 to purchase, staff will install. | J31: =I31*0.1 -> 0 | L31: =SUM(I31*0.1) -> 0 | M31: =I31*0.07 -> 0 | N31: =SUM(I31:M31) -> 0 | T31: =IF(N31<150000,"3",IF(N31<500000,"2",IF(N31>500000,"1"))) -> 3 | Y31: =SUM(P31:X31)/8 -> 0
B32: R-128 | C32: Security Cameras - Cavalero | E32: Security cameras for Cavalero Park. | J32: =I32*0.1 -> 0 | L32: =SUM(I32*0.1) -> 0 | M32: =I32*0.07 -> 0 | N32: =SUM(I32:M32) -> 0 | T32: =IF(N32<150000,"3",IF(N32<500000,"2",IF(N32>500000,"1"))) -> 3 | Y32: =SUM(P32:X32)/8 -> 0
B33: R-129 | C33: Monument/Entrance Sign - Cavalero | E33: The City will be acquiring Cavalero Park from the County. This park will need a City entry sign to match our standards, which consists of a base and blue sign displaying the park name and address. | J33: =I33*0.1 -> 0 | L33: =SUM(I33*0.1) -> 0 | M33: =I33*0.07 -> 0 | N33: =SUM(I33:M33) -> 0 | T33: =IF(N33<150000,"3",IF(N33<500000,"2",IF(N33>500000,"1"))) -> 3 | Y33: =SUM(P33:X33)/8 -> 0
B34: R-130 | C34: North Cove Parking Lot & Recreation Building Design | E34: Design and Engineering. Remove one of the administrative buildings, repurpose the other and construct new parking lot | J34: =I34*0.1 -> 0 | L34: =SUM(I34*0.1) -> 0 | M34: =I34*0.07 -> 0 | N34: =SUM(I34:M34) -> 0 | T34: =IF(N34<150000,"3",IF(N34<500000,"2",IF(N34>500000,"1"))) -> 3 | Y34: =SUM(P34:X34)/8 -> 0
J35: =I35*0.1 -> 0 | L35: =SUM(I35*0.1) -> 0 | M35: =I35*0.07 -> 0 | N35: =SUM(I35:M35) -> 0 | T35: =IF(N35<150000,"3",IF(N35<500000,"2",IF(N35>500000,"1"))) -> 3 | Y35: =SUM(P35:X35)/8 -> 0
J36: =I36*0.1 -> 0 | L36: =SUM(I36*0.1) -> 0 | M36: =I36*0.07 -> 0 | N36: =SUM(I36:M36) -> 0 | T36: =IF(N36<150000,"3",IF(N36<500000,"2",IF(N36>500000,"1"))) -> 3 | Y36: =SUM(P36:X36)/8 -> 0
J37: =I37*0.1 -> 0 | L37: =SUM(I37*0.1) -> 0 | M37: =I37*0.07 -> 0 | N37: =SUM(I37:M37) -> 0 | T37: =IF(N37<150000,"3",IF(N37<500000,"2",IF(N37>500000,"1"))) -> 3 | Y37: =SUM(P37:X37)/8 -> 0
J38: =I38*0.1 -> 0 | L38: =SUM(I38*0.1) -> 0 | M38: =I38*0.07 -> 0 | N38: =SUM(I38:M38) -> 0 | T38: =IF(N38<150000,"3",IF(N38<500000,"2",IF(N38>500000,"1"))) -> 3 | Y38: =SUM(P38:X38)/8 -> 0
J39: =I39*0.1 -> 0 | L39: =SUM(I39*0.1) -> 0 | M39: =I39*0.07 -> 0 | N39: =SUM(I39:M39) -> 0 | T39: =IF(N39<150000,"3",IF(N39<500000,"2",IF(N39>500000,"1"))) -> 3 | Y39: =SUM(P39:X39)/8 -> 0
J40: =I40*0.1 -> 0 | L40: =SUM(I40*0.1) -> 0 | M40: =I40*0.07 -> 0 | N40: =SUM(I40:M40) -> 0 | T40: =IF(N40<150000,"3",IF(N40<500000,"2",IF(N40>500000,"1"))) -> 3 | Y40: =SUM(P40:X40)/8 -> 0
J41: =I41*0.1 -> 0 | L41: =SUM(I41*0.1) -> 0 | M41: =I41*0.07 -> 0 | N41: =SUM(I41:M41) -> 0 | T41: =IF(N41<150000,"3",IF(N41<500000,"2",IF(N41>500000,"1"))) -> 3 | Y41: =SUM(P41:X41)/8 -> 0

Sheet Surface Water
A2: Capital Facilities Plan - Stormwater
A3: Project Number | B3: Project Name | C3: Location | D3: Description | E3: 2022 Budget | F3: Construction Estimate | G3: A&E | H3: ROW/Property | I3: Contingency | J3: Construction Management | K3: Total Cost | L3: Land Use | M3: Flood Mitigation Benefit/Risk Mitigation | N3: Environmental/ Sustainability | O3: Operational/ Budget Impact | P3: Cost | Q3: Opportunity | R3: Partnership Opportunity | S3: Grant Eligibility | T3: Dedicated Funding | U3: Average Score | W3: Surface Water - Scoring Criteria
A4: SW-105 | B4: 20th Street NE Culvert Replacement/Channel realignment | D4: Phase II - Downtown Flood Mitigation: Replacement of the 20th Street NE culvert with a bridge to reduce the severity and occurrence of flooding in the downtown area. This project includes channel realignment. | F4: 3200000 | G4: =F4*0.1 -> 320000 | H4: 100000 | I4: =SUM(F4*0.1) -> 320000 | J4: =F4*0.07 -> 224000 | K4: =SUM(F4:J4) -> 4164000 | L4: 3 | M4: 3 | N4: 3 | O4: 3 | P4: 1 | Q4: 3 | R4: 2 | S4: 2 | T4: 1 | U4: =SUM(L4:T4)/6 -> 3.5 | W4: Priority | X4: Land Use | Y4: Flood Mitigation Benefit/Risk Mitigation | Z4: Environmental/ Sustainability | AA4: Operational/ Budget Impact | AB4: Cost | AC4: Opportunity | AD4: Partnership Opportunity | AE4: Grant Eligibility | AF4: Dedicated Funding
A5: SW-106 | B5: Hartford Crossing - New and Channel realignment | D5: Phase III - Downtown Flood Mitigation: Replacement of two culverts on Hartford Drive with bridges and channel restoration through the wetland west of Hartford. | F5: 5500000 | G5: =F5*0.1 -> 550000 | H5: 10000 | I5: =SUM(F5*0.1) -> 550000 | J5: =F5*0.07 -> 385000 | K5: =SUM(F5:J5) -> 6995000 | L5: 3 | M5: 3 | N5: 3 | O5: 3 | P5: 1 | Q5: 3 | R5: 2 | S5: 2 | T5: 1 | U5: =SUM(L5:T5)/6 -> 3.5 | W5: High = 3 | X5: Commercial | Y5: >5 Structures Mitigated | Z5: Total Fish Barrier Restored | AA5: Substantial reduction in operational costs | AB5: <$150,000 | AC5: Public Support is Strong and Political Support is Strong | AD5: Agreement in place | AE5: Eligible for more than two grants | AF5: Full Funding
A6: SW-101 | B6: Weir Replacement | D6: Phase I - Downtown Flood Mitigation: Replacement of the weir at the outlet of Lake Stevens with a control structure that provides fish passage and automated control of the lake level. | E6: 75000 | F6: 750000 | G6: =F6*0.1 -> 75000 | H6: 0 | I6: =SUM(F6*0.1) -> 75000 | J6: =F6*0.07 -> 52500 | K6: =SUM(F6:J6) -> 952500 | L6: 3 | M6: 3 | N6: 3 | O6: 3 | P6: 1 | Q6: 3 | R6: 3 | S6: 1 | T6: 1 | U6: =SUM(L6:T6)/6 -> 3.5 | X6: Industrial | Y6: Minor Arterial | Z6: Stream Daylighted | AA6: Substantial reduction in financial risk | AD6: Infrastructure will be damaged if project is ont constructed
A7: SW-107 | B7: 18th Street NE Culvert Replacement/ realignment | D7: Phase IV - Downtown Flood Mitigation: Replacement of the 18th Street NE with a bridge. | F7: 1000000 | G7: =F7*0.1 -> 100000 | I7: =SUM(F7*0.1) -> 100000 | J7: =F7*0.07 -> 70000 | K7: =SUM(F7:J7) -> 1270000 | L7: 3 | M7: 3 | N7: 3 | O7: 3 | P7: 1 | Q7: 2 | R7: 2 | S7: 2 | T7: 1 | U7: =SUM(L7:T7)/6 -> 3.3333333 | Y7: Sole Access | Z7: Project Improves TMDL
A8: SW-104 | B8: Bridge 06 Replacement - 36th Street NE | D8: Bridge 06 requires a quarterly inspection due to structural concerns. This bridge should be replaced to ensure commercial traffic can access the Hartford Industrial area of the City. | F8: 2500000 | G8: =F8*0.1 -> 250000 | I8: =SUM(F8*0.1) -> 250000 | J8: =F8*0.07 -> 175000 | K8: =SUM(F8:J8) -> 3175000 | L8: 3 | M8: 3 | N8: 1 | O8: 3 | P8: 1 | Q8: 3 | R8: 1 | S8: 2 | T8: 1 | U8: =SUM(L8:T8)/6 -> 3
A9: SW-109 | B9: Regional Stormwater Facility Downtown | D9: Construct a regional stormwater facility in downtown Lake Stevens to encourage commercial growth. | F9: 1000000 | G9: =F9*0.1 -> 100000 | I9: =SUM(F9*0.1) -> 100000 | J9: =F9*0.07 -> 70000 | K9: =SUM(F9:J9) -> 1270000 | L9: 3 | M9: 2 | N9: 2 | O9: 2 | P9: 1 | Q9: 2 | R9: 2 | S9: 1 | T9: 1 | U9: =SUM(L9:T9)/6 -> 2.6666667
A10: SW-110 | B10: Regional Stormwater Facility Hartford Industrial | D10: Construct a regional stormwater facility in adjacent to Hartford Drive to encourage industrial growth. | F10: 1000000 | G10: =F10*0.1 -> 100000 | I10: =SUM(F10*0.1) -> 100000 | J10: =F10*0.07 -> 70000 | K10: =SUM(F10:J10) -> 1270000 | L10: 3 | M10: 2 | N10: 2 | O10: 2 | P10: 1 | Q10: 2 | R10: 2 | S10: 1 | T10: 1 | U10: =SUM(L10:T10)/6 -> 2.6666667
A11: SW-111 | B11: Catherine Creek/Hartford Crossing Replacement | F11: 2500000 | G11: =F11*0.1 -> 250000 | I11: =SUM(F11*0.1) -> 250000 | J11: =F11*0.07 -> 175000 | K11: =SUM(Table6[[#This Row],[Construction Estimate]:[Construction Management]]) -> 3175000 | L11: 3 | M11: 1 | N11: 2 | O11: 1 | P11: 1 | Q11: 3 | R11: 1 | S11: 3 | T11: 1 | U11: =SUM(L11:T11)/6 -> 2.6666667
A12: Sur | B12: 36th Street Culvert Replacement - Fish Passable | D12: Replace the culvert at 36th Street NE that conveys a tributary to Catherine Creek. | E12: 0 | F12: 600000 | G12: =F12*0.1 -> 60000 | I12: =SUM(F12*0.1) -> 60000 | J12: =F12*0.07 -> 42000 | K12: =SUM(F12:J12) -> 762000 | L12: 3 | M12: 2 | N12: 2 | O12: 1 | P12: 1 | Q12: 2 | R12: 2 | S12: 2 | T12: 1 | U12: =SUM(L12:T12)/6 -> 2.6666667
A13: SW-102 | B13: 10th/79th Storm Line Replacement | D13: Replacement of inadequately sized stormwater pipes and structures with structures/pipes to convey the significant quantity of water in this area. | E13: 100000 | F13: 400000 | G13: =F13*0.1 -> 40000 | I13: =SUM(F13*0.1) -> 40000 | J13: =F13*0.07 -> 28000 | K13: =SUM(F13:J13) -> 508000 | L13: 1 | M13: 2 | N13: 3 | O13: 3 | P13: 1 | Q13: 2 | R13: 1 | S13: 1 | T13: 1 | U13: =SUM(L13:T13)/6 -> 2.5
A14: SW-103 | B14: 99th Ave SE/4th St. SE Culvert Feasibility | D14: Design/feasibility of a culvert replacement project at 99th Ave SE/4th St. SE. | E14: 75000 | F14: 1500000 | G14: =F14*0.1 -> 150000 | I14: =SUM(F14*0.1) -> 150000 | J14: =F14*0.07 -> 105000 | K14: =SUM(F14:J14) -> 1905000 | L14: 1 | M14: 1 | N14: 1 | O14: 1 | P14: 1 | Q14: 1 | R14: 1 | S14: 1 | T14: 1 | U14: =SUM(L14:T14)/6 -> 1.5 | W14: Medium = 2 | X14: Multi-Family | Y14: >3 Structures Mitigated | Z14: Partial Fish Barrier Restored | AA14: Moderate reduction in operational costs | AB14: $150,001 to $500,000 | AC14: Public or Political Support Strong | AD14: Agreement is pending with support | AE14: Eligible for one grant | AF14: >50% Funded
A15: SW-112 | B15: SWM Fee - Rate Study and Fee Adoption | D15: This project is to hire a consultant to set surface water utility rates. Assess the stormwater management fee structure to ensure fair distribution of costs, compliance with regulations, and financial sustainability. This study should include staff needs, NPDES requirements, integrate actions from the basins plan, EMP, SMAP, and CCTV projects. The surface water utility fees have been set through 2027. The last rate study for the City took place in 2018. Since 2018, the City has inspected and inventoried all stormwater facility assets, set condition ratings for more than half of the stormwater conveyance infrastructure, identified capital projects, and completed long-range plan to address water quality by assessing enhanced maintenance standards, retrofits to existing infrastructure, and new capital projects. All of this information will be used in a new study to set utility rates. | G15: =F15*0.1 -> 0 | I15: =SUM(F15*0.1) -> 0 | J15: =F15*0.07 -> 0 | K15: =SUM(F15:J15) -> 0 | U15: =SUM(L15:T15)/6 -> 0
